Workbook

Sheet GRAPH
A1: =Y1&" "&"Wafer Lot: "&Y2&" SEE QUALIFIED EPI ID: " & Y3 & " " & "WAFERS: " & Y4 -> EPC7014UBSH Wafer Lot: E3637M SEE QUALIFIED EPI ID: 3621A1761 WAFERS: WAFER NO, P090, P091, P098, P099 | X1: PRODUCT | Y1: EPC7014UBSH
A2: ="WAFERS QUALIFIED: " & Y4 -> WAFERS QUALIFIED: WAFER NO, P090, P091, P098, P099 | X2: ELOT | Y2: E3637M
A3: ="15MeV " & Y5 & " Beam LET=" & Y6 & " Beam Energy: " & Y7 &"MeV Range: " & Y8 &"µm VDS=" & Y9 & "V, VGS=" & Y10 &"V" -> 15MeV AU Beam LET=82.3 Beam Energy: 2374MeV Range: 127.5µm VDS=60V, VGS=-4V | X3: EPI ID | Y3: 3621A1761
A4: ="Fluence = " & TEXT(Y13,"0.00E+0") &" Flux = " & TEXT(Y14,"0.00E+0") -> Fluence = 1.00E+7 Flux = 4.83E+4 | X4: WAFERS | Y4: WAFER NO, P090, P091, P098, P099 | Z4: P091, P099
A5: ="IDS <" &Y21*1000000 & " µA @VDS=" & Z9 &"V IGSSF<" & Y11*1000 &"mA @VGS=" & AA11 & "V IGSSR<" & Y12*1000000 & "uA @ VGS=" & AA12 & "V" -> IDS <100 µA @VDS=60V IGSSF<0.5mA @VGS=6V IGSSR<-100uA @ VGS=-4V | X5: ION | Y5: AU
A6: ="Run Ends at Fluence of " & TEXT(Y13,"0.00E+0") -> Run Ends at Fluence of 1.00E+7 | X6: LET | Y6: 82.3
A7: ="Tested at: "&Y15&" on: "& TEXT(Y16,"MM/DD/YYYY") -> Tested at: Texas A&M University on: 04/18/2023 | X7: ENERGY | Y7: 2374
X8: LENGTH | Y8: 127.5
X9: VDS | Y9: 60 | Z9: 60
X10: VGS | Y10: -4
X11: IGSSF | Y11: 0.0005 | Z11: VGS | AA11: 6
X12: IGSSR | Y12: -0.0001 | Z12: VGS | AA12: -4
X13: FLUENCE | Y13: 10000000
X14: FLUX | Y14: 48300
X15: LOCATION | Y15: Texas A&M University
X16: SEE DATE | Y16: 45034
X20: IDS MAX LIMIT
X21: 0 | Y21: 0.0001
X22: 10000000 | Y22: 0.0001
X24: IGSR MAX LIMIT
X25: 0 | Y25: -0.0001
X26: 10000000 | Y26: -0.0001
X28: ="IDS_" & AA28 &"_" & Wafer1!C1 -> IDS__P091-1 | Y28: ="IGS_" & AA28 &"_" & Wafer1!C1 -> IGS__P091-1 | AB28: 98
X29: ="IDS_"&AA29&"_ " & Wafer1!G1 -> IDS__ P091-2 | Y29: ="IGS_" & AA29 &"_" &Wafer1!G1 -> IGS__P091-2 | AB29: 99
X30: ="IDS_" & AA30 &"_"& Wafer1!K1 -> IDS__P091-3 | Y30: ="IGS_" & AA30 &"_" &Wafer1!K1 -> IGS__P091-3 | AB30: 100
X31: ="IDS_" & AA31 &"_" & Wafer1!O1 -> IDS__P099-1 | Y31: ="IGS_" & AA31 &"_" &Wafer1!O1 -> IGS__P099-1 | AB31: 94
X32: ="IDS_" & AA32 &"_" & Wafer1!S1 -> IDS__P099-2 | Y32: ="IGS_"&AA32&"_"&Wafer1!S1 -> IGS__P099-2 | AB32: 95
X33: ="IDS_" & AA33&"_" & Wafer1!W1 -> IDS__P099-3 | Y33: ="IGS_"&AA33&"_"&Wafer1!W1 -> IGS__P099-3 | AB33: 96
X34: ="IDS_" & AA34 &"_" & Wafer1!AA1 -> IDS__P099-4 | Y34: ="IGS_" & AA34 &"_" & Wafer1!AA1 -> IGS__P099-4 | AB34: 97
X35: ="IDS_" & AA35 &"_" & Wafer1!AE1 -> IDS__ | Y35: ="IGS_" & AA35 &"_" &Wafer1!AE1 -> IGS__
X36: ="IDS_" &AA36&"_" & Wafer1!AI1 -> IDS__ | Y36: ="IGS_" & AA36 &"_" &Wafer1!AI1 -> IGS__
X37: ="IDS_" &AA37 &"_" & Wafer1!AM1 -> IDS__ | Y37: ="IGS_" &AA37 &"_" &Wafer1!AM1 -> IGS__
A38: Operator | B38: MZ/JB | G38: Operator | H38: MZ/JB | X38: ="IDS_" &AA38 &"_" & Wafer1!AQ1 -> IDS__ | Y38: ="IGS_" &AA38 &"_" &Wafer1!AQ1 -> IGS__
A39: Station | B39: SEE TEST STATION | G39: Station | H39: SEE TEST STATION | X39: ="IDS_" &AA39 &"_" & Wafer1!AU1 -> IDS__ | Y39: ="IGS_" &AA39 &"_" &Wafer1!AU1 -> IGS__
A40: Lot Number | B40: =Y2 -> E3637M | G40: Lot Number | H40: =Y2 -> E3637M
A41: Process | B41: SEE TESTING | G41: Process | H41: SEE TESTING
A42: Start Date | B42: =Y16 -> 45034 | G42: Start Date | H42: =Y16 -> 45034
A43: Finish Date | B43: =Y16 -> 45034 | G43: Finish Date | H43: =Y16 -> 45034
A44: Part Number | B44: =Y1 -> EPC7014UBSH | G44: Part Number | H44: =Y1 -> EPC7014UBSH
A45: Process | B45: PRE SEE | G45: Remarks | H45: POST SEE
...

Sheet Wafer1
A1: P091 | C1: P091-1 | E1: P091 | G1: P091-2 | I1: P091 | K1: P091-3 | M1: P099 | O1: P099-1 | Q1: P099 | S1: P099-2 | U1: P099 | W1: P099-3 | Y1: P099 | AA1: P099-4
A2: 0 | B2: 2.95e-08 | C2: 1.73e-08 | E2: 0 | F2: 3.02e-08 | G2: 3.6e-08 | I2: 0 | J2: 1.81e-08 | K2: 6.7e-08 | M2: 0 | N2: 8.38e-09 | O2: 3.53e-08 | Q2: 0 | R2: 4.34e-08 | S2: 2.75e-08 | U2: 0 | V2: 3.18e-08 | W2: 1.96e-08 | Y2: 0 | Z2: 4.3e-08 | AA2: 3.03e-08
A3: 0 | B3: 2.28e-08 | C3: 3.1e-08 | E3: 0 | F3: 2.805e-08 | G3: 3.72e-08 | I3: 0 | J3: 1.79e-08 | K3: 5.78e-08 | M3: 0 | N3: 2.519e-08 | O3: 2.905e-08 | Q3: 0 | R3: 4.14e-08 | S3: 2.47e-08 | U3: 0 | V3: 2.775e-08 | W3: 2.075e-08 | Y3: 0 | Z3: 2.446e-08 | AA3: 2.965e-08
A4: 0 | B4: 2.5e-08 | C4: 4.25e-08 | E4: 0 | F4: 2.8466667e-08 | G4: 3.64e-08 | I4: 0 | J4: 2.6066667e-08 | K4: 5.3933333e-08 | M4: 0 | N4: 3.1326667e-08 | O4: 2.7166667e-08 | Q4: 0 | R4: 2.9916667e-08 | S4: 2.4033333e-08 | U4: 0 | V4: 3.25e-08 | W4: 2.1933333e-08 | Y4: 0 | Z4: 1.984e-08 | AA4: 3.17e-08
A5: 8041.2086 | B5: 2.6725e-08 | C5: 4.14e-08 | E5: 0 | F5: 2.42e-08 | G5: 3.51e-08 | I5: 0 | J5: 2.4675e-08 | K5: 5.22e-08 | M5: 0 | N5: 3.4295e-08 | O5: 2.6525e-08 | Q5: 0 | R5: 2.87875e-08 | S5: 2.355e-08 | U5: 575.01832 | V5: 3.8275e-08 | W5: 1.79525e-08 | Y5: 0 | Z5: 2.513e-08 | AA5: 2.8325e-08
A6: 20035.787 | B6: 2.634e-08 | C6: 4.136e-08 | E6: 0 | F6: 2.674e-08 | G6: 3.564e-08 | I6: 8986.5686 | J6: 2.406e-08 | K6: 4.858e-08 | M6: 10693.697 | N6: 3.2136e-08 | O6: 2.194e-08 | Q6: 0 | R6: 3.207e-08 | S6: 2.402e-08 | U6: 14681.319 | V6: 3.696e-08 | W6: 1.8682e-08 | Y6: 0 | Z6: 2.8284e-08 | AA6: 2.644e-08
A7: 32944.751 | B7: 3.0883333e-08 | C7: 4.2933333e-08 | E7: 0 | F7: 2.42e-08 | G7: 3.4983333e-08 | I7: 19206.863 | J7: 2.4066667e-08 | K7: 4.8533333e-08 | M7: 21923.827 | N7: 3.138e-08 | O7: 1.6971667e-08 | Q7: 0 | R7: 3.0191667e-08 | S7: 2.4233333e-08 | U7: 29117.949 | V7: 3.6616667e-08 | W7: 1.9285e-08 | Y7: 0 | Z7: 3.1786667e-08 | AA7: 2.665e-08
A8: 46122.651 | B8: 3.77e-08 | C8: 4.7985714e-08 | E8: 0 | F8: 2.45e-08 | G8: 3.2857143e-08 | I8: 30702.941 | J8: 2.7257143e-08 | K8: 4.5085714e-08 | M8: 33352.205 | N8: 3.2754286e-08 | O8: 1.4631857e-08 | Q8: 0 | R8: 2.8478571e-08 | S8: 2.3585714e-08 | U8: 42698.168 | V8: 3.8828571e-08 | W8: 1.9887143e-08 | Y8: 0 | Z8: 3.2902857e-08 | AA8: 2.9857143e-08
A9: 60107.362 | B9: 4.00875e-08 | C9: 4.90125e-08 | E9: 0 | F9: 2.173e-08 | G9: 3.1275e-08 | I9: 42339.216 | J9: 2.94125e-08 | K9: 4.5425e-08 | M9: 45480.28 | N9: 3.401e-08 | O9: 1.4865375e-08 | Q9: 0 | R9: 2.824375e-08 | S9: 2.30625e-08 | U9: 55911.355 | V9: 3.92875e-08 | W9: 2.018875e-08 | Y9: 0 | Z9: 3.099e-08 | AA9: 2.8525e-08
A10: 73016.326 | B10: 4.6411111e-08 | C10: 4.8044444e-08 | E10: 0 | F10: 1.9607778e-08 | G10: 3.0688889e-08 | I10: 52433.333 | J10: 2.9833333e-08 | K10: 4.7322222e-08 | M10: 58424.667 | N10: 3.4331111e-08 | O10: 1.5202556e-08 | Q10: 0 | R10: 2.7905556e-08 | S10: 2.2755556e-08 | U10: 70470.33 | V10: 3.9355556e-08 | W10: 2.2545556e-08 | Y10: 0 | Z10: 3.178e-08 | AA10: 2.6677778e-08
A11: 86597.631 | B11: 4.938e-08 | C11: 5.151e-08 | E11: 0 | F11: 1.9427e-08 | G11: 3.114e-08 | I11: 62807.843 | J11: 3.143e-08 | K11: 4.656e-08 | M11: 69503.197 | N11: 3.3278e-08 | O11: 1.80823e-08 | Q11: 0 | R11: 2.7415e-08 | S11: 2.276e-08 | U11: 83805.861 | V11: 3.824e-08 | W11: 2.4651e-08 | Y11: 0 | Z11: 2.9972e-08 | AA11: 2.677e-08
A12: 98565.316 | B12: 5.4436364e-08 | C12: 5.24e-08 | E12: 0 | F12: 1.937e-08 | G12: 3.1172727e-08 | I12: 72761.765 | J12: 3.1109091e-08 | K12: 4.8690909e-08 | M12: 80931.575 | N12: 3.3070909e-08 | O12: 2.0811182e-08 | Q12: 0 | R12: 2.6968182e-08 | S12: 2.2772727e-08 | U12: 97386.081 | V12: 3.9190909e-08 | W12: 2.5391818e-08 | Y12: 0 | Z12: 2.972e-08 | AA12: 2.6881818e-08
A13: 111608.75 | B13: 5.75e-08 | C13: 5.215e-08 | E13: 0 | F13: 1.9580833e-08 | G13: 3.0725e-08 | I13: 83977.451 | J13: 3.2533333e-08 | K13: 5.1e-08 | M13: 92243.337 | N13: 3.3331667e-08 | O13: 2.118525e-08 | Q13: 0 | R13: 2.6754167e-08 | S13: 2.2566667e-08 | U13: 112923.81 | V13: 4.1133333e-08 | W13: 2.37325e-08 | Y13: 0 | Z13: 2.9951667e-08 | AA13: 2.6508333e-08
... A797: 9426232.8 | B797: 2.3695e-06 | C797: 6.9265e-07 | E797: 2134181.6 | F797: 4.5965e-07 | G797: 2.713e-08 | I797: 8986568.6 | J797: 1.957e-06 | K797: 3.704e-07 | M797: 8431344.2 | N797: 1.5915e-07 | O797: 6.285e-08 | Q797: 8985265.8 | R797: 1.8095e-07 | S797: 5.5075e-08 | U797: 10020000 | V797: 2.502e-07 | W797: 4.639e-08 | Y797: 450650.44 | Z797: 1.1837e-08 | AA797: 7.5525e-09
A798: 9439679.7 | B798: 2.3655e-06 | C798: 6.9605e-07 | E798: 2147950.5 | F798: 4.663e-07 | G798: 2.8675e-08 | I798: 8986568.6 | J798: 1.952e-06 | K798: 3.6645e-07 | M798: 8443005.8 | N798: 1.599e-07 | O798: 6.0975e-08 | Q798: 8997608.2 | R798: 1.809e-07 | S798: 5.4985e-08 | Y798: 450650.44 | Z798: 1.20905e-08 | AA798: 8.245e-09
A799: 9453126.5 | B799: 2.3715e-06 | C799: 6.998e-07 | E799: 2161719.4 | F799: 4.7155e-07 | G799: 3.0045e-08 | I799: 9000588.2 | J799: 1.9625e-06 | K799: 4.0865e-07 | M799: 8454667.4 | N799: 1.6125e-07 | O799: 6.0235e-08 | Q799: 9009950.6 | R799: 1.8135e-07 | S799: 5.433e-08 | Y799: 450650.44 | Z799: 1.2939e-08 | AA799: 8.45e-09
A800: 9466573.4 | B800: 2.3835e-06 | C800: 7.0435e-07 | E800: 2175488.3 | F800: 4.764e-07 | G800: 3.137e-08 | I800: 9014607.8 | J800: 1.9615e-06 | K800: 4.294e-07 | M800: 8466329.1 | N800: 1.619e-07 | O800: 6.1225e-08 | Q800: 9022293 | R800: 1.82e-07 | S800: 5.438e-08 | Y800: 450650.44 | Z800: 1.2799e-08 | AA800: 7.984e-09
A801: 9480020.2 | B801: 2.381e-06 | C801: 7.079e-07 | E801: 2189257.2 | F801: 4.8e-07 | G801: 3.218e-08 | I801: 9028627.5 | J801: 1.961e-06 | K801: 4.463e-07 | M801: 8477990.7 | N801: 1.6205e-07 | O801: 6.3015e-08 | Q801: 9034635.4 | R801: 1.826e-07 | S801: 5.4015e-08 | Y801: 450650.44 | Z801: 1.23855e-08 | AA801: 7.443e-09
A802: 9493467 | B802: 2.3865e-06 | C802: 7.099e-07 | E802: 2203026.1 | F802: 4.841e-07 | G802: 3.2775e-08 | I802: 9042647.1 | J802: 1.962e-06 | K802: 4.6495e-07 | M802: 8489652.3 | N802: 1.6225e-07 | O802: 6.424e-08 | Q802: 9046977.8 | R802: 1.8285e-07 | S802: 5.371e-08 | Y802: 450650.44 | Z802: 1.39225e-08 | AA802: 7.12312e-09
A803: 9493467 | B803: 2.39e-06 | C803: 7.1385e-07 | E803: 2216795 | F803: 4.905e-07 | G803: 3.365e-08 | I803: 9042647.1 | J803: 1.9565e-06 | K803: 5.1695e-07 | M803: 8489652.3 | N803: 1.6205e-07 | O803: 6.4835e-08 | Q803: 9059320.1 | R803: 1.831e-07 | S803: 5.326e-08 | Y803: 450650.44 | Z803: 1.47775e-08 | AA803: 8.55312e-09
A804: 9506913.9 | B804: 2.383e-06 | C804: 7.161e-07 | E804: 2216795 | F804: 4.9315e-07 | G804: 3.3715e-08 | I804: 9056666.7 | J804: 1.9375e-06 | K804: 5.587e-07 | M804: 8501313.9 | N804: 1.6265e-07 | O804: 6.471e-08 | Q804: 9071662.5 | R804: 1.855e-07 | S804: 5.293e-08 | Y804: 450650.44 | Z804: 1.60275e-08 | AA804: 9.14762e-09
A805: 9520360.7 | B805: 2.4e-06 | C805: 7.195e-07 | E805: 2230564 | F805: 4.9695e-07 | G805: 3.4605e-08 | I805: 9070686.3 | J805: 1.935e-06 | K805: 5.921e-07 | M805: 8512975.5 | N805: 1.637e-07 | O805: 6.64e-08 | Q805: 9084004.9 | R805: 1.857e-07 | S805: 5.3235e-08 | Y805: 450650.44 | Z805: 1.61475e-08 | AA805: 1.190762e-08
A806: 9533807.5 | B806: 2.398e-06 | C806: 7.2155e-07 | E806: 2244332.9 | F806: 4.988e-07 | G806: 3.6225e-08 | I806: 9070686.3 | J806: 1.9235e-06 | K806: 6.2715e-07 | M806: 8524637.1 | N806: 1.6395e-07 | O806: 6.5845e-08 | Q806: 9096347.3 | R806: 1.864e-07 | S806: 5.345e-08 | Y806: 450650.44 | Z806: 1.65325e-08 | AA806: 1.146612e-08
A807: 9547254.4 | B807: 2.391e-06 | C807: 6.6305e-07 | E807: 2258101.8 | F807: 5.0235e-07 | G807: 3.726e-08 | I807: 9084705.9 | J807: 1.9385e-06 | K807: 6.501e-07 | M807: 8536298.7 | N807: 1.658e-07 | O807: 6.541e-08 | Q807: 9108689.7 | R807: 1.871e-07 | S807: 5.339e-08 | Y807: 450650.44 | Z807: 1.5252e-08 | AA807: 9.99612e-09
A808: 9547254.4 | B808: 2.3955e-06 | C808: 6.249e-07 | E808: 2271870.7 | F808: 5.0495e-07 | G808: 3.8415e-08 | I808: 9098725.5 | J808: 1.94e-06 | K808: 6.6955e-07 | M808: 8547960.3 | N808: 1.6805e-07 | O808: 6.429e-08 | Q808: 9121032.1 | R808: 1.8735e-07 | S808: 5.3405e-08 | Y808: 450650.44 | Z808: 1.4503e-08 | AA808: 1.036062e-08
A809: 9560701.2 | B809: 2.379e-06 | C809: 5.901e-07 | E809: 2285639.6 | F809: 5.069e-07 | G809: 3.931e-08 | I809: 9112745.1 | J809: 1.9235e-06 | K809: 6.8875e-07 | M809: 8559621.9 | N809: 1.6955e-07 | O809: 6.3135e-08 | Q809: 9133374.5 | R809: 1.8995e-07 | S809: 5.3895e-08 | Y809: 450650.44 | Z809: 1.38375e-08 | AA809: 1.315562e-08
... A851: 9991000 | B851: 2.4875e-06 | C851: 4.3495e-07 | E851: 2561017.9 | F851: 5.1615e-07 | G851: 5.2555e-08 | I851: 9547352.9 | J851: 2.082e-06 | K851: 3.3835e-07 | M851: 9002763.1 | N851: 1.7375e-07 | O851: 1.06005e-07 | Q851: 9676440 | R851: 2.0235e-07 | S851: 4.8995e-08 | Y851: 450650.44 | Z851: 1.280645e-08 | AA851: 1.2695e-08
E852: 2561017.9 | F852: 5.168e-07 | G852: 5.222e-08 | I852: 9561372.5 | J852: 2.066e-06 | K852: 3.3215e-07 | M852: 9014424.7 | N852: 1.7345e-07 | O852: 1.02845e-07 | Q852: 9688782.4 | R852: 2.0045e-07 | S852: 5.011e-08 | Y852: 450650.44 | Z852: 1.394095e-08 | AA852: 1.191e-08
E853: 2574786.8 | F853: 5.165e-07 | G853: 5.1485e-08 | I853: 9575392.2 | J853: 2.067e-06 | K853: 3.25e-07 | M853: 9026086.3 | N853: 1.7285e-07 | O853: 1.0093e-07 | Q853: 9701124.8 | R853: 1.997e-07 | S853: 5.001e-08 | Y853: 450650.44 | Z853: 1.360045e-08 | AA853: 1.3021e-08
E854: 2588555.7 | F854: 5.189e-07 | G854: 5.042e-08 | I854: 9575392.2 | J854: 2.074e-06 | K854: 3.1725e-07 | M854: 9037748 | N854: 1.743e-07 | O854: 9.933e-08 | Q854: 9713467.2 | R854: 2.004e-07 | S854: 5.0385e-08 | Y854: 450650.44 | Z854: 1.469495e-08 | AA854: 1.41935e-08
E855: 2602324.6 | F855: 5.212e-07 | G855: 4.993e-08 | I855: 9589411.8 | J855: 2.0815e-06 | K855: 3.102e-07 | M855: 9049409.6 | N855: 1.7555e-07 | O855: 9.71e-08 | Q855: 9725809.6 | R855: 2e-07 | S855: 5.024e-08 | Y855: 450650.44 | Z855: 1.314995e-08 | AA855: 1.5251e-08
E856: 2616093.5 | F856: 5.2395e-07 | G856: 4.9565e-08 | I856: 9603431.4 | J856: 2.0825e-06 | K856: 3.0685e-07 | M856: 9049409.6 | N856: 1.7615e-07 | O856: 9.223e-08 | Q856: 9738152 | R856: 1.9955e-07 | S856: 5.0645e-08 | Y856: 450650.44 | Z856: 1.19324e-08 | AA856: 1.5376e-08
E857: 2629862.4 | F857: 5.2585e-07 | G857: 4.897e-08 | I857: 9617451 | J857: 2.0805e-06 | K857: 3.03e-07 | M857: 9061071.2 | N857: 1.763e-07 | O857: 8.855e-08 | Q857: 9750494.4 | R857: 2.002e-07 | S857: 5.084e-08 | Y857: 450650.44 | Z857: 1.30259e-08 | AA857: 1.4746e-08
E858: 2643631.4 | F858: 5.271e-07 | G858: 4.8615e-08 | I858: 9631470.6 | J858: 2.0875e-06 | K858: 2.9765e-07 | M858: 9072732.8 | N858: 1.7735e-07 | O858: 8.597e-08 | Q858: 9762836.8 | R858: 2.001e-07 | S858: 5.0665e-08 | Y858: 450650.44 | Z858: 1.31414e-08 | AA858: 1.4866e-08
E859: 2657400.3 | F859: 5.2785e-07 | G859: 4.879e-08 | I859: 9631470.6 | J859: 2.0995e-06 | K859: 2.9255e-07 | M859: 9084394.4 | N859: 1.78e-07 | O859: 8.3585e-08 | Q859: 9775179.2 | R859: 1.9935e-07 | S859: 5.0125e-08 | Y859: 450650.44 | Z859: 1.29764e-08 | AA859: 1.58305e-08
E860: 2671169.2 | F860: 5.3125e-07 | G860: 4.848e-08 | I860: 9645490.2 | J860: 2.092e-06 | K860: 2.838e-07 | M860: 9096056 | N860: 1.7935e-07 | O860: 8.164e-08 | Q860: 9787521.6 | R860: 1.992e-07 | S860: 4.977e-08 | Y860: 450650.44 | Z860: 1.374845e-08 | AA860: 1.5281e-08
E861: 2684938.1 | F861: 5.3395e-07 | G861: 4.798e-08 | I861: 9659509.8 | J861: 2.0925e-06 | K861: 2.7825e-07 | M861: 9107717.6 | N861: 1.816e-07 | O861: 8.109e-08 | Q861: 9799864 | R861: 1.9935e-07 | S861: 4.9715e-08 | Y861: 450650.44 | Z861: 1.336845e-08 | AA861: 1.38805e-08
E862: 2684938.1 | F862: 5.3695e-07 | G862: 4.871e-08 | I862: 9673529.4 | J862: 2.0965e-06 | K862: 2.749e-07 | M862: 9119379.2 | N862: 1.8255e-07 | O862: 8.0635e-08 | Q862: 9812206.4 | R862: 1.994e-07 | S862: 5.011e-08 | Y862: 450650.44 | Z862: 1.257595e-08 | AA862: 1.3918e-08
E863: 2698707 | F863: 5.397e-07 | G863: 5.0035e-08 | I863: 9673529.4 | J863: 2.116e-06 | K863: 2.717e-07 | M863: 9131040.8 | N863: 1.837e-07 | O863: 8.078e-08 | Q863: 9824548.8 | R863: 2.001e-07 | S863: 4.9875e-08 | Y863: 450650.44 | Z863: 1.224345e-08 | AA863: 1.4058e-08
... E878: 2877702.9 | F878: 5.9965e-07 | G878: 5.66e-08 | I878: 9841764.7 | J878: 2.1265e-06 | K878: 2.7275e-07 | M878: 9282641.8 | N878: 2.2675e-07 | O878: 6.56e-08 | Q878: 9985000 | R878: 1.9725e-07 | S878: 4.3525e-08 | Y878: 450650.44 | Z878: 7.98515e-09 | AA878: 9.645e-09
...
