Workbook

Sheet GRAPH
A1: =T1&" "&"Wafer Lot: "&T2&" SEE QUALIFIED EPI ID: " & T3 & " " & "WAFERS: " & T4 -> EPC7018KH Wafer Lot: E4759M SEE QUALIFIED EPI ID: G323900362 WAFERS: WAFER NO, D001, D002, D162, D163, D170 | S1: PRODUCT | T1: EPC7018KH
A2: ="WAFERS QUALIFIED: " & T4 -> WAFERS QUALIFIED: WAFER NO, D001, D002, D162, D163, D170 | S2: ELOT | T2: E4759M
A3: ="15MeV " & T5 & " Beam LET=" & T6 & " Beam Energy: " & T7 &"MeV Range: " & T8 &"µm VDS=" & T9 & "V, VGS=" & T10 &"V" -> 15MeV AU Beam LET=82.3 Beam Energy: 2373.5MeV Range: 127.5µm VDS=100V, VGS=-1V | S3: EPI ID | T3: G323900362
A4: ="Fluence = " & TEXT(T13,"0.00E+0") &" Flux = " & TEXT(T14,"0.00E+0") -> Fluence = 1.00E+7 Flux = 5.11E+4 | S4: WAFERS | T4: WAFER NO, D001, D002, D162, D163, D170 | U4: D001, D002
A5: ="IDS <" &T21*1000000 & " µA @VDS=" & U9 &"V IGSSF<" & T11*1000 &"mA @VGS=" & V11 & "V IGSSR<" & T12*1000000 & "uA @ VGS=" & V12 & "V" -> IDS <400 µA @VDS=100V IGSSF<0.5mA @VGS=6V IGSSR<-500uA @ VGS=-1V | S5: ION | T5: AU
A6: ="Run Ends at Fluence of " & TEXT(T13,"0.00E+0") -> Run Ends at Fluence of 1.00E+7 | S6: LET | T6: 82.3
A7: ="Tested at: "&T15&" on: "& TEXT(T16,"MM/DD/YYYY") -> Tested at: Texas A&M University on: 08/12/2024 | S7: ENERGY | T7: 2373.5
S8: LENGTH | T8: 127.5
S9: VDS | T9: 100 | U9: 100
S10: VGS | T10: -1
S11: IGSSF | T11: 0.0005 | U11: VGS | V11: 6
S12: IGSSR | T12: -0.0005 | U12: VGS | V12: -1
S13: FLUENCE | T13: 10000000
S14: FLUX | T14: 51100
S15: LOCATION | T15: Texas A&M University
S16: SEE DATE | T16: 45516
S20: IDS MAX LIMIT
S21: 0 | T21: 0.0004
S22: 10000000 | T22: 0.0004
S24: IGSR MAX LIMIT
S25: 0 | T25: -0.0005
S26: 10000000 | T26: -0.0005
S28: ="IDS_" & V28 &"_" & Wafer1!C1 -> IDS__D001-1 | T28: ="IGS_" & V28 &"_" & Wafer1!C1 -> IGS__D001-1 | W28: 121
S29: ="IDS_"&V29&"_ " & Wafer1!G1 -> IDS__ D001-2 | T29: ="IGS_" & V29 &"_" &Wafer1!G1 -> IGS__D001-2 | W29: 122
S30: ="IDS_" & V30 &"_"& Wafer1!K1 -> IDS__D001-3 | T30: ="IGS_" & V30 &"_" &Wafer1!K1 -> IGS__D001-3 | W30: 123
S31: ="IDS_" & V31 &"_" & Wafer1!O1 -> IDS__D002-1 | T31: ="IGS_" & V31 &"_" &Wafer1!O1 -> IGS__D002-1 | W31: 125
S32: ="IDS_" & V32 &"_" & Wafer1!S1 -> IDS__D002-2 | T32: ="IGS_"&V32&"_"&Wafer1!S1 -> IGS__D002-2 | W32: 126
S33: ="IDS_" & V33&"_" & Wafer1!W1 -> IDS__D002-3 | T33: ="IGS_"&V33&"_"&Wafer1!W1 -> IGS__D002-3 | W33: 127
S34: ="IDS_" & V34 &"_" & Wafer1!AA1 -> IDS__ | T34: ="IGS_" & V34 &"_" & Wafer1!AA1 -> IGS__
S35: ="IDS_" & V35 &"_" & Wafer1!AE1 -> IDS__ | T35: ="IGS_" & V35 &"_" &Wafer1!AE1 -> IGS__
S36: ="IDS_" &V36&"_" & Wafer1!AI1 -> IDS__ | T36: ="IGS_" & V36 &"_" &Wafer1!AI1 -> IGS__
S37: ="IDS_" &V37 &"_" & Wafer1!AM1 -> IDS__ | T37: ="IGS_" &V37 &"_" &Wafer1!AM1 -> IGS__
A38: Operator | B38: MZ/JB | G38: Operator | H38: MZ/JB | S38: ="IDS_" &V38 &"_" & Wafer1!AQ1 -> IDS__ | T38: ="IGS_" &V38 &"_" &Wafer1!AQ1 -> IGS__
A39: Station | B39: SEE TEST STATION | G39: Station | H39: SEE TEST STATION | S39: ="IDS_" &V39 &"_" & Wafer1!AU1 -> IDS__ | T39: ="IGS_" &V39 &"_" &Wafer1!AU1 -> IGS__
A40: Lot Number | B40: =T2 -> E4759M | G40: Lot Number | H40: =T2 -> E4759M
A41: Process | B41: SEE TESTING | G41: Process | H41: SEE TESTING
A42: Start Date | B42: =T16 -> 45516 | G42: Start Date | H42: =T16 -> 45516
A43: Finish Date | B43: =T16 -> 45516 | G43: Finish Date | H43: =T16 -> 45516
A44: Part Number | B44: =T1 -> EPC7018KH | G44: Part Number | H44: =T1 -> EPC7018KH
A45: Process | B45: PRE SEE | G45: Remarks | H45: POST SEE
...

Sheet Wafer1
A1: D001 | C1: D001-1 | E1: D001 | G1: D001-2 | I1: D001 | K1: D001-3 | M1: D002 | O1: D002-1 | Q1: D002 | S1: D002-2 | U1: D002 | W1: D002-3
A2: 0 | B2: 6.52e-07 | C2: 1.88e-07 | E2: 0 | F2: 5.78e-07 | G2: 2.38e-07 | I2: 0 | J2: 2.59e-07 | K2: 1.65e-07 | M2: 0 | N2: 1.1e-06 | O2: 2.09e-07 | Q2: 0 | R2: 3.29e-06 | S2: 4.92e-07 | U2: 0 | V2: 6.7e-07 | W2: 2.03e-07
A3: 0 | B3: 6.43e-07 | C3: 1.875e-07 | E3: 0 | F3: 5.72e-07 | G3: 2.375e-07 | I3: 0 | J3: 2.575e-07 | K3: 1.655e-07 | M3: 0 | N3: 1.075e-06 | O3: 2.125e-07 | Q3: 0 | R3: 3.305e-06 | S3: 4.94e-07 | U3: 0 | V3: 6.645e-07 | W3: 2.175e-07
A4: 0 | B4: 9.8866667e-07 | C4: 1.8966667e-07 | E4: 0 | F4: 1.0446667e-06 | G4: 2.3966667e-07 | I4: 0 | J4: 4.2366667e-07 | K4: 1.6533333e-07 | M4: 0 | N4: 1.2366667e-06 | O4: 2.1366667e-07 | Q4: 0 | R4: 3.4033333e-06 | S4: 4.9733333e-07 | U4: 0 | V4: 9.6966667e-07 | W4: 2.2866667e-07
A5: 2164.6925 | B5: 1.1965e-06 | C5: 1.865e-07 | E5: 8804.4318 | F5: 1.241e-06 | G5: 2.4e-07 | I5: 176.45283 | J5: 7.3775e-07 | K5: 1.6475e-07 | M5: 1674.7748 | N5: 1.3475e-06 | O5: 2.14e-07 | Q5: 10187.171 | R5: 3.4875e-06 | S5: 4.965e-07 | U5: 8057.0939 | V5: 1.18475e-06 | W5: 2.31e-07
A6: 16702.874 | B6: 1.4112e-06 | C6: 1.836e-07 | E6: 23266.967 | F6: 1.5188e-06 | G6: 2.408e-07 | I6: 15502.642 | J6: 1.0442e-06 | K6: 1.662e-07 | M6: 16103.604 | N6: 1.572e-06 | O6: 2.128e-07 | Q6: 21820.263 | R6: 3.604e-06 | S6: 4.968e-07 | U6: 17183.376 | V6: 1.3438e-06 | W6: 2.298e-07
A7: 30198.797 | B7: 1.5426667e-06 | C7: 1.81e-07 | E7: 37015.629 | F7: 1.8423333e-06 | G7: 2.4133333e-07 | I7: 29366.792 | J7: 1.2885e-06 | K7: 1.6716667e-07 | M7: 31434.234 | N7: 1.7666667e-06 | O7: 2.1216667e-07 | Q7: 26946.711 | R7: 3.7366667e-06 | S7: 4.955e-07 | U7: 27875.254 | V7: 1.4965e-06 | W7: 2.2633333e-07
A8: 43293.85 | B8: 1.6951429e-06 | C8: 1.7928571e-07 | E8: 51028.689 | F8: 2.1948571e-06 | G8: 2.4114286e-07 | I8: 43230.943 | J8: 1.523e-06 | K8: 1.6714286e-07 | M8: 47022.523 | N8: 1.9485714e-06 | O8: 2.1157143e-07 | Q8: 39565.658 | R8: 3.8342857e-06 | S8: 4.9457143e-07 | U8: 42894.797 | V8: 1.657e-06 | W8: 2.2428571e-07
A9: 55052.674 | B9: 1.83575e-06 | C9: 1.775e-07 | E9: 64248.556 | F9: 2.443e-06 | G9: 2.41e-07 | I9: 58103.396 | J9: 1.750125e-06 | K9: 1.65375e-07 | M9: 60163.063 | N9: 2.1225e-06 | O9: 2.11125e-07 | Q9: 47978.289 | R9: 3.92875e-06 | S9: 4.94125e-07 | U9: 54732.234 | V9: 1.834875e-06 | W9: 2.25e-07
A10: 66811.497 | B10: 2.0606667e-06 | C10: 1.7655556e-07 | E10: 77071.828 | F10: 2.6437778e-06 | G10: 2.4111111e-07 | I10: 70959.245 | J10: 1.9967778e-06 | K10: 1.6355556e-07 | M10: 76266.667 | N10: 2.2733333e-06 | O10: 2.1044444e-07 | Q10: 55339.342 | R10: 4.04e-06 | S10: 4.9011111e-07 | U10: 73570.305 | V10: 2.0254444e-06 | W10: 2.2533333e-07
A11: 81643.65 | B11: 2.3106e-06 | C11: 1.763e-07 | E11: 89630.702 | F11: 2.8784e-06 | G11: 2.411e-07 | I11: 84697.358 | J11: 2.2581e-06 | K11: 1.627e-07 | M11: 87217.117 | N11: 2.438e-06 | O11: 2.099e-07 | Q11: 62043.158 | R11: 4.11e-06 | S11: 4.89e-07 | U11: 86044.162 | V11: 2.1849e-06 | W11: 2.241e-07
A12: 93402.473 | B12: 2.5523636e-06 | C12: 1.7627273e-07 | E12: 102850.57 | F12: 3.1685455e-06 | G12: 2.4118182e-07 | I12: 98057.358 | J12: 2.5137273e-06 | K12: 1.6263636e-07 | M12: 102032.43 | N12: 2.5981818e-06 | O12: 2.0945455e-07 | Q12: 77948.289 | R12: 4.2127273e-06 | S12: 4.88e-07 | U12: 97627.03 | V12: 2.3544545e-06 | W12: 2.2318182e-07
A13: 107299.26 | B13: 2.8121667e-06 | C13: 1.7758333e-07 | E13: 116863.63 | F13: 3.4278333e-06 | G13: 2.4091667e-07 | I13: 113181.89 | J13: 2.7259167e-06 | K13: 1.6258333e-07 | M13: 118264.86 | N13: 2.7516667e-06 | O13: 2.0891667e-07 | Q13: 87018.158 | R13: 4.31e-06 | S13: 4.8683333e-07 | U13: 112773.86 | V13: 2.5165833e-06 | W13: 2.2333333e-07
... A742: 9995000 | B742: 0.0002301 | C742: 3.004e-07 | E742: 8844091.4 | F742: 0.0002248 | G742: 2.8385e-07 | I742: 9616679.2 | J742: 0.0002287 | K742: 2.7385e-07 | M742: 8708828.8 | N742: 0.00023535 | O742: 2.7915e-07 | Q742: 7689671.1 | R742: 0.00019455 | S742: 2.2515e-07 | U742: 7382487.3 | V742: 0.00023305 | W742: 2.3655e-07
E743: 8857311.3 | F743: 0.0002251 | G743: 2.8345e-07 | I743: 9629283 | J743: 0.000229 | K743: 2.7455e-07 | M743: 8721711.7 | N743: 0.0002358 | O743: 2.7935e-07 | Q743: 7702815.8 | R743: 0.00019505 | S743: 2.2575e-07 | U743: 7407944.2 | V743: 0.0002336 | W743: 2.352e-07
E744: 8857311.3 | F744: 0.0002254 | G744: 2.8375e-07 | I744: 9641886.8 | J744: 0.0002293 | K744: 2.7455e-07 | M744: 8734594.6 | N744: 0.0002362 | O744: 2.7955e-07 | Q744: 7715960.5 | R744: 0.0001956 | S744: 2.2615e-07 | U744: 7420672.6 | V744: 0.00023415 | W744: 2.3475e-07
E745: 8870531.1 | F745: 0.0002257 | G745: 2.84e-07 | I745: 9654490.6 | J745: 0.0002296 | K745: 2.7515e-07 | M745: 8747477.5 | N745: 0.0002366 | O745: 2.797e-07 | Q745: 7729105.3 | R745: 0.00019605 | S745: 2.279e-07 | U745: 7433401 | V745: 0.0002347 | W745: 2.3335e-07
E746: 8883751 | F746: 0.000226 | G746: 2.843e-07 | I746: 9667094.3 | J746: 0.0002299 | K746: 2.7525e-07 | M746: 8747477.5 | N746: 0.000237 | O746: 2.7985e-07 | Q746: 7742250 | R746: 0.0001966 | S746: 2.2875e-07 | U746: 7446129.4 | V746: 0.0002352 | W746: 2.3115e-07
E747: 8896970.9 | F747: 0.0002263 | G747: 2.842e-07 | I747: 9679698.1 | J747: 0.0002302 | K747: 2.757e-07 | M747: 8760360.4 | N747: 0.0002374 | O747: 2.798e-07 | Q747: 7768539.5 | R747: 0.00019715 | S747: 2.3e-07 | U747: 7458857.9 | V747: 0.00023575 | W747: 2.2935e-07
E748: 8896970.9 | F748: 0.0002266 | G748: 2.839e-07 | I748: 9692301.9 | J748: 0.0002305 | K748: 2.7575e-07 | M748: 8773243.2 | N748: 0.00023785 | O748: 2.7995e-07 | Q748: 7781684.2 | R748: 0.00019765 | S748: 2.306e-07 | U748: 7471586.3 | V748: 0.00023615 | W748: 2.2765e-07
E749: 8910190.7 | F749: 0.0002269 | G749: 2.838e-07 | I749: 9704905.7 | J749: 0.0002308 | K749: 2.76e-07 | M749: 8786126.1 | N749: 0.0002383 | O749: 2.8005e-07 | Q749: 7794828.9 | R749: 0.00019815 | S749: 2.318e-07 | U749: 7484314.7 | V749: 0.0002366 | W749: 2.2715e-07
E750: 8923410.6 | F750: 0.0002272 | G750: 2.838e-07 | I750: 9717509.4 | J750: 0.0002311 | K750: 2.7685e-07 | M750: 8799009 | N750: 0.00023875 | O750: 2.8025e-07 | Q750: 7807973.7 | R750: 0.0001987 | S750: 2.332e-07 | U750: 7497043.1 | V750: 0.000237 | W750: 2.2565e-07
E751: 8936630.5 | F751: 0.0002275 | G751: 2.8355e-07 | I751: 9717509.4 | J751: 0.0002314 | K751: 2.7765e-07 | M751: 8824774.8 | N751: 0.00023915 | O751: 2.806e-07 | Q751: 7834263.2 | R751: 0.0001992 | S751: 2.3385e-07 | U751: 7509771.6 | V751: 0.0002375 | W751: 2.2585e-07
E752: 8949850.3 | F752: 0.0002278 | G752: 2.831e-07 | I752: 9730113.2 | J752: 0.0002317 | K752: 2.7815e-07 | M752: 8837657.7 | N752: 0.0002396 | O752: 2.8105e-07 | Q752: 7847407.9 | R752: 0.00019975 | S752: 2.346e-07 | U752: 7522500 | V752: 0.000238 | W752: 2.2695e-07
E753: 8949850.3 | F753: 0.0002281 | G753: 2.829e-07 | I753: 9742717 | J753: 0.000232 | K753: 2.785e-07 | M753: 8850540.5 | N753: 0.0002401 | O753: 2.811e-07 | Q753: 7860552.6 | R753: 0.00020025 | S753: 2.349e-07 | U753: 7535228.4 | V753: 0.00023855 | W753: 2.2715e-07
E754: 8963070.2 | F754: 0.0002284 | G754: 2.8285e-07 | I754: 9755320.8 | J754: 0.0002323 | K754: 2.788e-07 | M754: 8863423.4 | N754: 0.0002406 | O754: 2.813e-07 | Q754: 7873697.4 | R754: 0.0002008 | S754: 2.357e-07 | U754: 7560685.3 | V754: 0.00023905 | W754: 2.261e-07
... E778: 9214247.7 | F778: 0.0002356 | G778: 2.848e-07 | I778: 10020000 | J778: 0.0002395 | K778: 2.8325e-07 | M778: 9146846.8 | N778: 0.0002508 | O778: 2.82e-07 | Q778: 8189171.1 | R778: 0.00021065 | S778: 2.38e-07 | U778: 7878895.9 | V778: 0.00024935 | W778: 2.402e-07
E779: 9227467.5 | F779: 0.0002359 | G779: 2.8535e-07 | M779: 9159729.7 | N779: 0.0002513 | O779: 2.8205e-07 | Q779: 8202315.8 | R779: 0.0002111 | S779: 2.388e-07 | U779: 7891624.4 | V779: 0.00024985 | W779: 2.3855e-07
E780: 9240687.4 | F780: 0.0002362 | G780: 2.8585e-07 | M780: 9172612.6 | N780: 0.00025165 | O780: 2.8215e-07 | Q780: 8215460.5 | R780: 0.00021155 | S780: 2.395e-07 | U780: 7904352.8 | V780: 0.00025045 | W780: 2.3755e-07
E781: 9253907.3 | F781: 0.0002365 | G781: 2.8595e-07 | M781: 9185495.5 | N781: 0.00025215 | O781: 2.823e-07 | Q781: 8228605.3 | R781: 0.00021195 | S781: 2.3935e-07 | U781: 7929809.6 | V781: 0.0002511 | W781: 2.358e-07
E782: 9253907.3 | F782: 0.0002368 | G782: 2.854e-07 | M782: 9185495.5 | N782: 0.0002526 | O782: 2.8245e-07 | Q782: 8254894.7 | R782: 0.0002124 | S782: 2.3955e-07 | U782: 7942538.1 | V782: 0.0002516 | W782: 2.3385e-07
E783: 9267127.2 | F783: 0.0002371 | G783: 2.85e-07 | M783: 9198378.4 | N783: 0.000253 | O783: 2.8275e-07 | Q783: 8268039.5 | R783: 0.00021285 | S783: 2.3995e-07 | U783: 7942538.1 | V783: 0.00025215 | W783: 2.3095e-07
E784: 9280347 | F784: 0.0002374 | G784: 2.8475e-07 | M784: 9211261.3 | N784: 0.0002534 | O784: 2.8315e-07 | Q784: 8281184.2 | R784: 0.00021335 | S784: 2.404e-07 | U784: 7955266.5 | V784: 0.00025275 | W784: 2.298e-07
E785: 9293566.9 | F785: 0.0002377 | G785: 2.8465e-07 | M785: 9224144.1 | N785: 0.00025375 | O785: 2.836e-07 | Q785: 8281184.2 | R785: 0.0002138 | S785: 2.398e-07 | U785: 7980723.4 | V785: 0.0002534 | W785: 2.2825e-07
E786: 9306786.8 | F786: 0.000238 | G786: 2.845e-07 | M786: 9224144.1 | N786: 0.00025415 | O786: 2.8395e-07 | Q786: 8307473.7 | R786: 0.0002143 | S786: 2.393e-07 | U786: 7993451.8 | V786: 0.000254 | W786: 2.261e-07
E787: 9306786.8 | F787: 0.0002383 | G787: 2.842e-07 | M787: 9237027 | N787: 0.0002546 | O787: 2.8445e-07 | Q787: 8320618.4 | R787: 0.0002148 | S787: 2.39e-07 | U787: 8006180.2 | V787: 0.0002546 | W787: 2.248e-07
E788: 9320006.6 | F788: 0.0002386 | G788: 2.8425e-07 | M788: 9249909.9 | N788: 0.000255 | O788: 2.846e-07 | Q788: 8333763.2 | R788: 0.00021525 | S788: 2.379e-07 | U788: 8018908.6 | V788: 0.0002552 | W788: 2.2355e-07
E789: 9333226.5 | F789: 0.0002389 | G789: 2.841e-07 | M789: 9262792.8 | N789: 0.00025545 | O789: 2.8455e-07 | Q789: 8346907.9 | R789: 0.0002157 | S789: 2.377e-07 | U789: 8031637.1 | V789: 0.0002557 | W789: 2.2085e-07
E790: 9346446.4 | F790: 0.0002392 | G790: 2.838e-07 | M790: 9262792.8 | N790: 0.0002558 | O790: 2.848e-07 | Q790: 8360052.6 | R790: 0.0002162 | S790: 2.3725e-07 | U790: 8044365.5 | V790: 0.0002562 | W790: 2.2e-07
... E856: 9981000 | F856: 0.000259 | G856: 2.8735e-07 | M856: 9984234.2 | N856: 0.0002781 | O856: 2.998e-07 | Q856: 9280184.2 | R856: 0.00024615 | S856: 2.0985e-07 | U856: 8935355.3 | V856: 0.00029095 | W856: 2.6355e-07
...
